Workbook

Sheet DEMIRBAS_TAKIP
A1: TAM ÖDEME | G1: EKSİK ÖDEME | H1: ÖDEME YOK | J1: FAZLA ÖDEME | L1: Temmuz | N1: Ağustos | P1: Eylül | R1: TOPLAM
A2: S.NO. | C2: BLOK | D2: DAİRE NO | E2: NİTELİGİ | F2: MT2 | G2: KAT MALİKİ İSMİ | H2: TELEFON NO | I2: KİRACI İSMİ | J2: TELEFON NO | K2: Sabit Aidat | L2: Tahakkuk | M2: Ödeme | N2: Tahakkuk | O2: Ödeme | P2: Tahakkuk | Q2: Ödeme | R2: Tahakkuk | S2: Ödeme
A3: 1 | B3: A-BLOK KREŞ | C3: A | D3: 1 | G3: Sinan Ünsal | K3: 10000 | L3: 4000 | N3: 3000 | P3: 3000 | R3: 10000 | S3: =SUM(M3,O3,Q3) -> 0
A4: 2 | B4: A-BLOK DAİRE 02 | C4: A | D4: 2 | G4: Rıdvan sansar | K4: 10000 | L4: 4000 | M4: 4000 | N4: 3000 | P4: 3000 | R4: 10000 | S4: =SUM(M4,O4,Q4) -> 4000
A5: 3 | B5: A-BLOK DAİRE 03 | C5: A | D5: 3 | G5: Sinan Ünsal | K5: 10000 | L5: 4000 | N5: 3000 | P5: 3000 | R5: 10000 | S5: =SUM(M5,O5,Q5) -> 0
A6: 4 | B6: A-BLOK DAİRE 04 | C6: A | D6: 4 | G6: BERKCAN DEMİRDÖĞEN | K6: 10000 | L6: 4000 | M6: 4000 | N6: 3000 | P6: 3000 | R6: 10000 | S6: =SUM(M6,O6,Q6) -> 4000
A7: 5 | B7: A-BLOK DAİRE 05 | C7: A | D7: 5 | G7: Sinan Ünsal | K7: 10000 | L7: 4000 | N7: 3000 | P7: 3000 | R7: 10000 | S7: =SUM(M7,O7,Q7) -> 0
A8: 6 | B8: A-BLOK DAİRE 06 | C8: A | D8: 6 | G8: Sinan Ünsal | K8: 10000 | L8: 4000 | N8: 3000 | P8: 3000 | R8: 10000 | S8: =SUM(M8,O8,Q8) -> 0
A9: 7 | B9: A-BLOK DAİRE 07 | C9: A | D9: 7 | G9: Sinan Ural | K9: 10000 | L9: 4000 | N9: 3000 | P9: 3000 | R9: 10000 | S9: =SUM(M9,O9,Q9) -> 0
A10: 8 | B10: A-BLOK DAİRE 08 | C10: A | D10: 8 | G10: Özgür Bozkurt | K10: 10000 | L10: 4000 | N10: 3000 | P10: 3000 | R10: 10000 | S10: =SUM(M10,O10,Q10) -> 0
A11: 9 | B11: A-BLOK DAİRE 09 | C11: A | D11: 9 | G11: Numan Küçük | K11: 10000 | L11: 4000 | N11: 3000 | P11: 3000 | R11: 10000 | S11: =SUM(M11,O11,Q11) -> 0
A12: 10 | B12: A-BLOK DAİRE 10 | C12: A | D12: 10 | G12: Murat Yıldırım | K12: 10000 | L12: 4000 | N12: 3000 | P12: 3000 | R12: 10000 | S12: =SUM(M12,O12,Q12) -> 0
A13: 11 | B13: A-BLOK DAİRE 11 | C13: A | D13: 11 | G13: Bülent Kermen | K13: 10000 | L13: 4000 | M13: 4000 | N13: 3000 | P13: 3000 | R13: 10000 | S13: =SUM(M13,O13,Q13) -> 4000
A14: 12 | B14: A-BLOK DAİRE 12 | C14: A | D14: 12 | G14: Semiha Tüzün | K14: 10000 | L14: 4000 | N14: 3000 | P14: 3000 | R14: 10000 | S14: =SUM(M14,O14,Q14) -> 0
A15: 13 | B15: A-BLOK DAİRE 13 | C15: A | D15: 13 | G15: Ahmet Aykut YILDIZ | K15: 10000 | L15: 4000 | M15: 4000 | N15: 3000 | O15: 3000 | P15: 3000 | Q15: 3000 | R15: 10000 | S15: =SUM(M15,O15,Q15) -> 10000
A16: 14 | B16: A-BLOK DAİRE 14 | C16: A | D16: 14 | G16: Uğur Burak Meriç | K16: 10000 | L16: 4000 | N16: 3000 | P16: 3000 | R16: 10000 | S16: =SUM(M16,O16,Q16) -> 0
A17: 15 | B17: A-BLOK DAİRE 15 | C17: A | D17: 15 | G17: Soner Çağlayan | K17: 10000 | L17: 4000 | M17: 4000 | N17: 3000 | O17: 3000 | P17: 3000 | Q17: 3000 | R17: 10000 | S17: =SUM(M17,O17,Q17) -> 10000
A18: 16 | B18: A-BLOK DAİRE 16 | C18: A | D18: 16 | G18: Muhammet Ali Bulut | K18: 10000 | L18: 4000 | N18: 3000 | P18: 3000 | R18: 10000 | S18: =SUM(M18,O18,Q18) -> 0
A19: 17 | B19: A-BLOK DAİRE 17 | C19: A | D19: 17 | G19: Gamze Şengün | K19: 10000 | L19: 4000 | M19: 4000 | N19: 3000 | P19: 3000 | R19: 10000 | S19: =SUM(M19,O19,Q19) -> 4000
A20: 18 | B20: A-BLOK DAİRE 18 | C20: A | D20: 18 | G20: Sude Karabulut | K20: 10000 | L20: 4000 | N20: 3000 | P20: 3000 | R20: 10000 | S20: =SUM(M20,O20,Q20) -> 0
A21: 19 | B21: A-BLOK DAİRE 19 | C21: A | D21: 19 | G21: Nesimi yanar | K21: 10000 | L21: 4000 | M21: 4000 | N21: 3000 | O21: 3000 | P21: 3000 | R21: 10000 | S21: =SUM(M21,O21,Q21) -> 7000
A22: 20 | B22: A-BLOK DAİRE 20 | C22: A | D22: 20 | G22: Murat Doğruyol | K22: 10000 | L22: 4000 | N22: 3000 | P22: 3000 | R22: 10000 | S22: =SUM(M22,O22,Q22) -> 0
A23: 21 | B23: A-BLOK DAİRE 21 | C23: A | D23: 21 | G23: Mehmet Saruhan | K23: 10000 | L23: 4000 | N23: 3000 | P23: 3000 | R23: 10000 | S23: =SUM(M23,O23,Q23) -> 0
A24: 22 | B24: A-BLOK DAİRE 22 | C24: A | D24: 22 | G24: Filiz Bora | K24: 10000 | L24: 4000 | N24: 3000 | P24: 3000 | R24: 10000 | S24: =SUM(M24,O24,Q24) -> 0
A25: 23 | B25: A-BLOK DAİRE 23 | C25: A | D25: 23 | G25: Kemal Aradan | K25: 10000 | L25: 4000 | N25: 3000 | P25: 3000 | R25: 10000 | S25: =SUM(M25,O25,Q25) -> 0
A26: 24 | B26: A-BLOK DAİRE 24 | C26: A | D26: 24 | G26: Nevin Köyatası | K26: 10000 | L26: 4000 | M26: 4000 | N26: 3000 | O26: 3000 | P26: 3000 | Q26: 3000 | R26: 10000 | S26: =SUM(M26,O26,Q26) -> 10000
A27: 25 | B27: A-BLOK DAİRE 25 | C27: A | D27: 25 | G27: Ümit Kula | K27: 10000 | L27: 4000 | N27: 3000 | P27: 3000 | R27: 10000 | S27: =SUM(M27,O27,Q27) -> 0
A28: 26 | B28: A-BLOK DAİRE 26 | C28: A | D28: 26 | G28: Hüsnü Sümer | K28: 10000 | L28: 4000 | M28: 4000 | N28: 3000 | O28: 3000 | P28: 3000 | R28: 10000 | S28: =SUM(M28,O28,Q28) -> 7000
A29: 27 | B29: A-BLOK DAİRE 27 | C29: A | D29: 27 | G29: Lütfiye Metin | K29: 10000 | L29: 4000 | N29: 3000 | P29: 3000 | R29: 10000 | S29: =SUM(M29,O29,Q29) -> 0
A30: 1 | B30: B-BLOK KAPICI D. | C30: B | D30: 0 | G30: KAPICI DAİRESİ | K30: 10000 | L30: 4000 | N30: 3000 | P30: 3000 | R30: 10000 | S30: =SUM(M30,O30,Q30) -> 0
A31: 2 | B31: B-BLOK DAİRE 01 | C31: B | D31: 1 | G31: Emine Keçeci | K31: 10000 | L31: 4000 | N31: 3000 | P31: 3000 | R31: 10000 | S31: =SUM(M31,O31,Q31) -> 0
A32: 3 | B32: B-BLOK DAİRE 02 | C32: B | D32: 2 | G32: Sinan Ünsal | K32: 10000 | L32: 4000 | N32: 3000 | P32: 3000 | R32: 10000 | S32: =SUM(M32,O32,Q32) -> 0
A33: 4 | B33: B-BLOK DAİRE 03 | C33: B | D33: 3 | G33: Lütfiye Metin | K33: 10000 | L33: 4000 | N33: 3000 | P33: 3000 | R33: 10000 | S33: =SUM(M33,O33,Q33) -> 0
A34: 5 | B34: B-BLOK DAİRE 04 | C34: B | D34: 4 | G34: Mehmet Keçeci | K34: 10000 | L34: 4000 | N34: 3000 | P34: 3000 | R34: 10000 | S34: =SUM(M34,O34,Q34) -> 0
A35: 6 | B35: B-BLOK DAİRE 05 | C35: B | D35: 5 | G35: Emine Keçeci | K35: 10000 | L35: 4000 | N35: 3000 | P35: 3000 | R35: 10000 | S35: =SUM(M35,O35,Q35) -> 0
A36: 7 | B36: B-BLOK DAİRE 06 | C36: B | D36: 6 | G36: Necmi Çavdar | K36: 10000 | L36: 4000 | N36: 3000 | P36: 3000 | R36: 10000 | S36: =SUM(M36,O36,Q36) -> 0
A37: 8 | B37: B-BLOK DAİRE 07 | C37: B | D37: 7 | G37: Sinan Ünsal | K37: 10000 | L37: 4000 | N37: 3000 | P37: 3000 | R37: 10000 | S37: =SUM(M37,O37,Q37) -> 0
A38: 9 | B38: B-BLOK DAİRE 08 | C38: B | D38: 8 | G38: Mehmet Keçeci | K38: 10000 | L38: 4000 | N38: 3000 | P38: 3000 | R38: 10000 | S38: =SUM(M38,O38,Q38) -> 0
A39: 10 | B39: B-BLOK DAİRE 09 | C39: B | D39: 9 | G39: Şerife Büyükgaga | K39: 10000 | L39: 4000 | M39: 4000 | N39: 3000 | O39: 3000 | P39: 3000 | Q39: 3000 | R39: 10000 | S39: =SUM(M39,O39,Q39) -> 10000
A40: 11 | B40: B-BLOK DAİRE 10 | C40: B | D40: 10 | G40: Sinan Ünsal | K40: 10000 | L40: 4000 | N40: 3000 | P40: 3000 | R40: 10000 | S40: =SUM(M40,O40,Q40) -> 0
...

Sheet AIDAT_DOGALGAZ_TAKIP
A1: TAM ÖDEME | G1: EKSİK ÖDEME | H1: ÖDEME YOK | J1: FAZLA ÖDEME | L1: 45292 | O1: 45323 | Q1: 45352 | S1: 45383 | U1: 45413 | W1: 45444 | Y1: 45474 | AA1: 45505 | AC1: 45536 | AE1: 45566 | AG1: 45597 | AI1: 45627
A2: S.NO. | C2: BLOK | D2: DAİRE NO | E2: NİTELİGİ | F2: MT2 | G2: KAT MALİKİ İSMİ | H2: TELEFON NO | I2: KİRACI İSMİ | J2: TELEFON NO | K2: Sabit Aidat | L2: Tahakkuk | M2: Tahakkuk | N2: Ödeme | O2: Tahakkuk | P2: Ödeme | Q2: Tahakkuk | R2: Ödeme | S2: Tahakkuk | T2: Ödeme | U2: Tahakkuk | V2: Ödeme | W2: Tahakkuk | X2: Ödeme | Y2: Tahakkuk | Z2: Ödeme | AA2: Tahakkuk | AB2: Ödeme | AC2: Tahakkuk | AD2: Ödeme | AE2: Tahakkuk | AF2: Ödeme | AG2: Tahakkuk | AH2: Ödeme | AI2: Tahakkuk | AJ2: Ödeme
A3: 1 | B3: A-BLOK KREŞ | C3: A | D3: 1 | G3: Sinan Ünsal | K3: 1500 | W3: =$K3+VLOOKUP($B3,Tablo1[],MONTH(W$1)+4,0) -> 1500 | Y3: =$K3+VLOOKUP($B3,Tablo1[],MONTH(Y$1)+4,0) -> 1500 | AA3: =$K3+VLOOKUP($B3,Tablo1[],MONTH(AA$1)+4,0) -> 1500 | AC3: =$K3+VLOOKUP($B3,Tablo1[],MONTH(AC$1)+4,0) -> 1500 | AE3: =$K3+VLOOKUP($B3,Tablo1[],MONTH(AE$1)+4,0) -> 1500 | AG3: =$K3+VLOOKUP($B3,Tablo1[],MONTH(AG$1)+4,0) -> 1500 | AI3: =$K3+VLOOKUP($B3,Tablo1[],MONTH(AI$1)+4,0) -> 1500
A4: 2 | B4: A-BLOK DAİRE 02 | C4: A | D4: 2 | G4: Rıdvan sansar | K4: 1500 | W4: =$K4+VLOOKUP($B4,Tablo1[],MONTH(W$1)+4,0) -> 1500 | X4: 1500 | Y4: =$K4+VLOOKUP($B4,Tablo1[],MONTH(Y$1)+4,0) -> 1500 | Z4: 1500 | AA4: =$K4+VLOOKUP($B4,Tablo1[],MONTH(AA$1)+4,0) -> 1500 | AC4: =$K4+VLOOKUP($B4,Tablo1[],MONTH(AC$1)+4,0) -> 1500 | AE4: =$K4+VLOOKUP($B4,Tablo1[],MONTH(AE$1)+4,0) -> 1500 | AG4: =$K4+VLOOKUP($B4,Tablo1[],MONTH(AG$1)+4,0) -> 1500 | AI4: =$K4+VLOOKUP($B4,Tablo1[],MONTH(AI$1)+4,0) -> 1500
A5: 3 | B5: A-BLOK DAİRE 03 | C5: A | D5: 3 | G5: Sinan Ünsal | K5: 1500 | W5: =$K5+VLOOKUP($B5,Tablo1[],MONTH(W$1)+4,0) -> 1500 | Y5: =$K5+VLOOKUP($B5,Tablo1[],MONTH(Y$1)+4,0) -> 1500 | AA5: =$K5+VLOOKUP($B5,Tablo1[],MONTH(AA$1)+4,0) -> 1500 | AC5: =$K5+VLOOKUP($B5,Tablo1[],MONTH(AC$1)+4,0) -> 1500 | AE5: =$K5+VLOOKUP($B5,Tablo1[],MONTH(AE$1)+4,0) -> 1500 | AG5: =$K5+VLOOKUP($B5,Tablo1[],MONTH(AG$1)+4,0) -> 1500 | AI5: =$K5+VLOOKUP($B5,Tablo1[],MONTH(AI$1)+4,0) -> 1500
A6: 4 | B6: A-BLOK DAİRE 04 | C6: A | D6: 4 | G6: BERKCAN DEMİRDÖĞEN | K6: 1500 | W6: =$K6+VLOOKUP($B6,Tablo1[],MONTH(W$1)+4,0) -> 1500 | X6: 1500 | Y6: =$K6+VLOOKUP($B6,Tablo1[],MONTH(Y$1)+4,0) -> 1500 | Z6: 1500 | AA6: =$K6+VLOOKUP($B6,Tablo1[],MONTH(AA$1)+4,0) -> 1500 | AC6: =$K6+VLOOKUP($B6,Tablo1[],MONTH(AC$1)+4,0) -> 1500 | AE6: =$K6+VLOOKUP($B6,Tablo1[],MONTH(AE$1)+4,0) -> 1500 | AG6: =$K6+VLOOKUP($B6,Tablo1[],MONTH(AG$1)+4,0) -> 1500 | AI6: =$K6+VLOOKUP($B6,Tablo1[],MONTH(AI$1)+4,0) -> 1500
A7: 5 | B7: A-BLOK DAİRE 05 | C7: A | D7: 5 | G7: Sinan Ünsal | K7: 1500 | W7: =$K7+VLOOKUP($B7,Tablo1[],MONTH(W$1)+4,0) -> 1500 | Y7: =$K7+VLOOKUP($B7,Tablo1[],MONTH(Y$1)+4,0) -> 1500 | AA7: =$K7+VLOOKUP($B7,Tablo1[],MONTH(AA$1)+4,0) -> 1500 | AC7: =$K7+VLOOKUP($B7,Tablo1[],MONTH(AC$1)+4,0) -> 1500 | AE7: =$K7+VLOOKUP($B7,Tablo1[],MONTH(AE$1)+4,0) -> 1500 | AG7: =$K7+VLOOKUP($B7,Tablo1[],MONTH(AG$1)+4,0) -> 1500 | AI7: =$K7+VLOOKUP($B7,Tablo1[],MONTH(AI$1)+4,0) -> 1500
A8: 6 | B8: A-BLOK DAİRE 06 | C8: A | D8: 6 | G8: Sinan Ünsal | K8: 1500 | W8: =$K8+VLOOKUP($B8,Tablo1[],MONTH(W$1)+4,0) -> 1500 | Y8: =$K8+VLOOKUP($B8,Tablo1[],MONTH(Y$1)+4,0) -> 1500 | AA8: =$K8+VLOOKUP($B8,Tablo1[],MONTH(AA$1)+4,0) -> 1500 | AC8: =$K8+VLOOKUP($B8,Tablo1[],MONTH(AC$1)+4,0) -> 1500 | AE8: =$K8+VLOOKUP($B8,Tablo1[],MONTH(AE$1)+4,0) -> 1500 | AG8: =$K8+VLOOKUP($B8,Tablo1[],MONTH(AG$1)+4,0) -> 1500 | AI8: =$K8+VLOOKUP($B8,Tablo1[],MONTH(AI$1)+4,0) -> 1500
A9: 7 | B9: A-BLOK DAİRE 07 | C9: A | D9: 7 | G9: Sinan Ural | K9: 1500 | W9: =$K9+VLOOKUP($B9,Tablo1[],MONTH(W$1)+4,0) -> 1500 | X9: 1500 | Y9: =$K9+VLOOKUP($B9,Tablo1[],MONTH(Y$1)+4,0) -> 1500 | Z9: 1500 | AA9: =$K9+VLOOKUP($B9,Tablo1[],MONTH(AA$1)+4,0) -> 1500 | AC9: =$K9+VLOOKUP($B9,Tablo1[],MONTH(AC$1)+4,0) -> 1500 | AE9: =$K9+VLOOKUP($B9,Tablo1[],MONTH(AE$1)+4,0) -> 1500 | AG9: =$K9+VLOOKUP($B9,Tablo1[],MONTH(AG$1)+4,0) -> 1500 | AI9: =$K9+VLOOKUP($B9,Tablo1[],MONTH(AI$1)+4,0) -> 1500
A10: 8 | B10: A-BLOK DAİRE 08 | C10: A | D10: 8 | G10: Özgür Bozkurt | K10: 1500 | W10: =$K10+VLOOKUP($B10,Tablo1[],MONTH(W$1)+4,0) -> 1500 | X10: 1500 | Y10: =$K10+VLOOKUP($B10,Tablo1[],MONTH(Y$1)+4,0) -> 1500 | Z10: 1500 | AA10: =$K10+VLOOKUP($B10,Tablo1[],MONTH(AA$1)+4,0) -> 1500 | AC10: =$K10+VLOOKUP($B10,Tablo1[],MONTH(AC$1)+4,0) -> 1500 | AE10: =$K10+VLOOKUP($B10,Tablo1[],MONTH(AE$1)+4,0) -> 1500 | AG10: =$K10+VLOOKUP($B10,Tablo1[],MONTH(AG$1)+4,0) -> 1500 | AI10: =$K10+VLOOKUP($B10,Tablo1[],MONTH(AI$1)+4,0) -> 1500
A11: 9 | B11: A-BLOK DAİRE 09 | C11: A | D11: 9 | G11: Numan Küçük | K11: 1500 | W11: =$K11+VLOOKUP($B11,Tablo1[],MONTH(W$1)+4,0) -> 1500 | Y11: =$K11+VLOOKUP($B11,Tablo1[],MONTH(Y$1)+4,0) -> 1500 | AA11: =$K11+VLOOKUP($B11,Tablo1[],MONTH(AA$1)+4,0) -> 1500 | AC11: =$K11+VLOOKUP($B11,Tablo1[],MONTH(AC$1)+4,0) -> 1500 | AE11: =$K11+VLOOKUP($B11,Tablo1[],MONTH(AE$1)+4,0) -> 1500 | AG11: =$K11+VLOOKUP($B11,Tablo1[],MONTH(AG$1)+4,0) -> 1500 | AI11: =$K11+VLOOKUP($B11,Tablo1[],MONTH(AI$1)+4,0) -> 1500
A12: 10 | B12: A-BLOK DAİRE 10 | C12: A | D12: 10 | G12: Murat Yıldırım | K12: 1500 | W12: =$K12+VLOOKUP($B12,Tablo1[],MONTH(W$1)+4,0) -> 1500 | Y12: =$K12+VLOOKUP($B12,Tablo1[],MONTH(Y$1)+4,0) -> 1500 | AA12: =$K12+VLOOKUP($B12,Tablo1[],MONTH(AA$1)+4,0) -> 1500 | AC12: =$K12+VLOOKUP($B12,Tablo1[],MONTH(AC$1)+4,0) -> 1500 | AE12: =$K12+VLOOKUP($B12,Tablo1[],MONTH(AE$1)+4,0) -> 1500 | AG12: =$K12+VLOOKUP($B12,Tablo1[],MONTH(AG$1)+4,0) -> 1500 | AI12: =$K12+VLOOKUP($B12,Tablo1[],MONTH(AI$1)+4,0) -> 1500
A13: 11 | B13: A-BLOK DAİRE 11 | C13: A | D13: 11 | G13: Bülent Kermen | K13: 1500 | W13: =$K13+VLOOKUP($B13,Tablo1[],MONTH(W$1)+4,0) -> 1500 | X13: 1500 | Y13: =$K13+VLOOKUP($B13,Tablo1[],MONTH(Y$1)+4,0) -> 1500 | Z13: 1500 | AA13: =$K13+VLOOKUP($B13,Tablo1[],MONTH(AA$1)+4,0) -> 1500 | AC13: =$K13+VLOOKUP($B13,Tablo1[],MONTH(AC$1)+4,0) -> 1500 | AE13: =$K13+VLOOKUP($B13,Tablo1[],MONTH(AE$1)+4,0) -> 1500 | AG13: =$K13+VLOOKUP($B13,Tablo1[],MONTH(AG$1)+4,0) -> 1500 | AI13: =$K13+VLOOKUP($B13,Tablo1[],MONTH(AI$1)+4,0) -> 1500
A14: 12 | B14: A-BLOK DAİRE 12 | C14: A | D14: 12 | G14: Semiha Tüzün | K14: 1500 | W14: =$K14+VLOOKUP($B14,Tablo1[],MONTH(W$1)+4,0) -> 1500 | X14: 1500 | Y14: =$K14+VLOOKUP($B14,Tablo1[],MONTH(Y$1)+4,0) -> 1500 | Z14: 1500 | AA14: =$K14+VLOOKUP($B14,Tablo1[],MONTH(AA$1)+4,0) -> 1500 | AC14: =$K14+VLOOKUP($B14,Tablo1[],MONTH(AC$1)+4,0) -> 1500 | AE14: =$K14+VLOOKUP($B14,Tablo1[],MONTH(AE$1)+4,0) -> 1500 | AG14: =$K14+VLOOKUP($B14,Tablo1[],MONTH(AG$1)+4,0) -> 1500 | AI14: =$K14+VLOOKUP($B14,Tablo1[],MONTH(AI$1)+4,0) -> 1500
A15: 13 | B15: A-BLOK DAİRE 13 | C15: A | D15: 13 | G15: Ahmet Aykut YILDIZ | K15: 1500 | W15: =$K15+VLOOKUP($B15,Tablo1[],MONTH(W$1)+4,0) -> 1500 | X15: 1500 | Y15: =$K15+VLOOKUP($B15,Tablo1[],MONTH(Y$1)+4,0) -> 1500 | Z15: 1500 | AA15: =$K15+VLOOKUP($B15,Tablo1[],MONTH(AA$1)+4,0) -> 1500 | AC15: =$K15+VLOOKUP($B15,Tablo1[],MONTH(AC$1)+4,0) -> 1500 | AE15: =$K15+VLOOKUP($B15,Tablo1[],MONTH(AE$1)+4,0) -> 1500 | AG15: =$K15+VLOOKUP($B15,Tablo1[],MONTH(AG$1)+4,0) -> 1500 | AI15: =$K15+VLOOKUP($B15,Tablo1[],MONTH(AI$1)+4,0) -> 1500
A16: 14 | B16: A-BLOK DAİRE 14 | C16: A | D16: 14 | G16: Uğur Burak Meriç | K16: 1500 | W16: =$K16+VLOOKUP($B16,Tablo1[],MONTH(W$1)+4,0) -> 1500 | Y16: =$K16+VLOOKUP($B16,Tablo1[],MONTH(Y$1)+4,0) -> 1500 | AA16: =$K16+VLOOKUP($B16,Tablo1[],MONTH(AA$1)+4,0) -> 1500 | AC16: =$K16+VLOOKUP($B16,Tablo1[],MONTH(AC$1)+4,0) -> 1500 | AE16: =$K16+VLOOKUP($B16,Tablo1[],MONTH(AE$1)+4,0) -> 1500 | AG16: =$K16+VLOOKUP($B16,Tablo1[],MONTH(AG$1)+4,0) -> 1500 | AI16: =$K16+VLOOKUP($B16,Tablo1[],MONTH(AI$1)+4,0) -> 1500
A17: 15 | B17: A-BLOK DAİRE 15 | C17: A | D17: 15 | G17: Soner Çağlayan | K17: 1500 | W17: =$K17+VLOOKUP($B17,Tablo1[],MONTH(W$1)+4,0) -> 1500 | X17: 1500 | Y17: =$K17+VLOOKUP($B17,Tablo1[],MONTH(Y$1)+4,0) -> 1500 | Z17: 1500 | AA17: =$K17+VLOOKUP($B17,Tablo1[],MONTH(AA$1)+4,0) -> 1500 | AC17: =$K17+VLOOKUP($B17,Tablo1[],MONTH(AC$1)+4,0) -> 1500 | AE17: =$K17+VLOOKUP($B17,Tablo1[],MONTH(AE$1)+4,0) -> 1500 | AG17: =$K17+VLOOKUP($B17,Tablo1[],MONTH(AG$1)+4,0) -> 1500 | AI17: =$K17+VLOOKUP($B17,Tablo1[],MONTH(AI$1)+4,0) -> 1500
A18: 16 | B18: A-BLOK DAİRE 16 | C18: A | D18: 16 | G18: Muhammet Ali Bulut | K18: 1500 | W18: =$K18+VLOOKUP($B18,Tablo1[],MONTH(W$1)+4,0) -> 1500 | X18: 1500 | Y18: =$K18+VLOOKUP($B18,Tablo1[],MONTH(Y$1)+4,0) -> 1500 | AA18: =$K18+VLOOKUP($B18,Tablo1[],MONTH(AA$1)+4,0) -> 1500 | AC18: =$K18+VLOOKUP($B18,Tablo1[],MONTH(AC$1)+4,0) -> 1500 | AE18: =$K18+VLOOKUP($B18,Tablo1[],MONTH(AE$1)+4,0) -> 1500 | AG18: =$K18+VLOOKUP($B18,Tablo1[],MONTH(AG$1)+4,0) -> 1500 | AI18: =$K18+VLOOKUP($B18,Tablo1[],MONTH(AI$1)+4,0) -> 1500
A19: 17 | B19: A-BLOK DAİRE 17 | C19: A | D19: 17 | G19: Gamze Şengün | K19: 1500 | W19: =$K19+VLOOKUP($B19,Tablo1[],MONTH(W$1)+4,0) -> 1500 | X19: 1500 | Y19: =$K19+VLOOKUP($B19,Tablo1[],MONTH(Y$1)+4,0) -> 1500 | Z19: 1500 | AA19: =$K19+VLOOKUP($B19,Tablo1[],MONTH(AA$1)+4,0) -> 1500 | AC19: =$K19+VLOOKUP($B19,Tablo1[],MONTH(AC$1)+4,0) -> 1500 | AE19: =$K19+VLOOKUP($B19,Tablo1[],MONTH(AE$1)+4,0) -> 1500 | AG19: =$K19+VLOOKUP($B19,Tablo1[],MONTH(AG$1)+4,0) -> 1500 | AI19: =$K19+VLOOKUP($B19,Tablo1[],MONTH(AI$1)+4,0) -> 1500
A20: 18 | B20: A-BLOK DAİRE 18 | C20: A | D20: 18 | G20: Sude Karabulut | K20: 1500 | W20: =$K20+VLOOKUP($B20,Tablo1[],MONTH(W$1)+4,0) -> 1500 | X20: 1500 | Y20: =$K20+VLOOKUP($B20,Tablo1[],MONTH(Y$1)+4,0) -> 1500 | Z20: 1500 | AA20: =$K20+VLOOKUP($B20,Tablo1[],MONTH(AA$1)+4,0) -> 1500 | AC20: =$K20+VLOOKUP($B20,Tablo1[],MONTH(AC$1)+4,0) -> 1500 | AE20: =$K20+VLOOKUP($B20,Tablo1[],MONTH(AE$1)+4,0) -> 1500 | AG20: =$K20+VLOOKUP($B20,Tablo1[],MONTH(AG$1)+4,0) -> 1500 | AI20: =$K20+VLOOKUP($B20,Tablo1[],MONTH(AI$1)+4,0) -> 1500
A21: 19 | B21: A-BLOK DAİRE 19 | C21: A | D21: 19 | G21: Nesimi yanar | K21: 1500 | W21: =$K21+VLOOKUP($B21,Tablo1[],MONTH(W$1)+4,0) -> 1500 | X21: 1500 | Y21: =$K21+VLOOKUP($B21,Tablo1[],MONTH(Y$1)+4,0) -> 1500 | Z21: 1500 | AA21: =$K21+VLOOKUP($B21,Tablo1[],MONTH(AA$1)+4,0) -> 1500 | AC21: =$K21+VLOOKUP($B21,Tablo1[],MONTH(AC$1)+4,0) -> 1500 | AE21: =$K21+VLOOKUP($B21,Tablo1[],MONTH(AE$1)+4,0) -> 1500 | AG21: =$K21+VLOOKUP($B21,Tablo1[],MONTH(AG$1)+4,0) -> 1500 | AI21: =$K21+VLOOKUP($B21,Tablo1[],MONTH(AI$1)+4,0) -> 1500
A22: 20 | B22: A-BLOK DAİRE 20 | C22: A | D22: 20 | G22: Murat Doğruyol | K22: 1500 | W22: =$K22+VLOOKUP($B22,Tablo1[],MONTH(W$1)+4,0) -> 1500 | Y22: =$K22+VLOOKUP($B22,Tablo1[],MONTH(Y$1)+4,0) -> 1500 | AA22: =$K22+VLOOKUP($B22,Tablo1[],MONTH(AA$1)+4,0) -> 1500 | AC22: =$K22+VLOOKUP($B22,Tablo1[],MONTH(AC$1)+4,0) -> 1500 | AE22: =$K22+VLOOKUP($B22,Tablo1[],MONTH(AE$1)+4,0) -> 1500 | AG22: =$K22+VLOOKUP($B22,Tablo1[],MONTH(AG$1)+4,0) -> 1500 | AI22: =$K22+VLOOKUP($B22,Tablo1[],MONTH(AI$1)+4,0) -> 1500
A23: 21 | B23: A-BLOK DAİRE 21 | C23: A | D23: 21 | G23: Mehmet Saruhan | K23: 1500 | W23: =$K23+VLOOKUP($B23,Tablo1[],MONTH(W$1)+4,0) -> 1500 | Y23: =$K23+VLOOKUP($B23,Tablo1[],MONTH(Y$1)+4,0) -> 1500 | AA23: =$K23+VLOOKUP($B23,Tablo1[],MONTH(AA$1)+4,0) -> 1500 | AC23: =$K23+VLOOKUP($B23,Tablo1[],MONTH(AC$1)+4,0) -> 1500 | AE23: =$K23+VLOOKUP($B23,Tablo1[],MONTH(AE$1)+4,0) -> 1500 | AG23: =$K23+VLOOKUP($B23,Tablo1[],MONTH(AG$1)+4,0) -> 1500 | AI23: =$K23+VLOOKUP($B23,Tablo1[],MONTH(AI$1)+4,0) -> 1500
A24: 22 | B24: A-BLOK DAİRE 22 | C24: A | D24: 22 | G24: Filiz Bora | K24: 1500 | W24: =$K24+VLOOKUP($B24,Tablo1[],MONTH(W$1)+4,0) -> 1500 | Y24: =$K24+VLOOKUP($B24,Tablo1[],MONTH(Y$1)+4,0) -> 1500 | AA24: =$K24+VLOOKUP($B24,Tablo1[],MONTH(AA$1)+4,0) -> 1500 | AC24: =$K24+VLOOKUP($B24,Tablo1[],MONTH(AC$1)+4,0) -> 1500 | AE24: =$K24+VLOOKUP($B24,Tablo1[],MONTH(AE$1)+4,0) -> 1500 | AG24: =$K24+VLOOKUP($B24,Tablo1[],MONTH(AG$1)+4,0) -> 1500 | AI24: =$K24+VLOOKUP($B24,Tablo1[],MONTH(AI$1)+4,0) -> 1500
A25: 23 | B25: A-BLOK DAİRE 23 | C25: A | D25: 23 | G25: Kemal Aradan | K25: 1500 | W25: =$K25+VLOOKUP($B25,Tablo1[],MONTH(W$1)+4,0) -> 1500 | Y25: =$K25+VLOOKUP($B25,Tablo1[],MONTH(Y$1)+4,0) -> 1500 | AA25: =$K25+VLOOKUP($B25,Tablo1[],MONTH(AA$1)+4,0) -> 1500 | AC25: =$K25+VLOOKUP($B25,Tablo1[],MONTH(AC$1)+4,0) -> 1500 | AE25: =$K25+VLOOKUP($B25,Tablo1[],MONTH(AE$1)+4,0) -> 1500 | AG25: =$K25+VLOOKUP($B25,Tablo1[],MONTH(AG$1)+4,0) -> 1500 | AI25: =$K25+VLOOKUP($B25,Tablo1[],MONTH(AI$1)+4,0) -> 1500
A26: 24 | B26: A-BLOK DAİRE 24 | C26: A | D26: 24 | G26: Nevin Köyatası | K26: 1500 | W26: =$K26+VLOOKUP($B26,Tablo1[],MONTH(W$1)+4,0) -> 1500 | X26: 1500 | Y26: =$K26+VLOOKUP($B26,Tablo1[],MONTH(Y$1)+4,0) -> 1500 | Z26: 1500 | AA26: =$K26+VLOOKUP($B26,Tablo1[],MONTH(AA$1)+4,0) -> 1500 | AC26: =$K26+VLOOKUP($B26,Tablo1[],MONTH(AC$1)+4,0) -> 1500 | AE26: =$K26+VLOOKUP($B26,Tablo1[],MONTH(AE$1)+4,0) -> 1500 | AG26: =$K26+VLOOKUP($B26,Tablo1[],MONTH(AG$1)+4,0) -> 1500 | AI26: =$K26+VLOOKUP($B26,Tablo1[],MONTH(AI$1)+4,0) -> 1500
A27: 25 | B27: A-BLOK DAİRE 25 | C27: A | D27: 25 | G27: Ümit Kula | K27: 1500 | W27: =$K27+VLOOKUP($B27,Tablo1[],MONTH(W$1)+4,0) -> 1500 | Y27: =$K27+VLOOKUP($B27,Tablo1[],MONTH(Y$1)+4,0) -> 1500 | AA27: =$K27+VLOOKUP($B27,Tablo1[],MONTH(AA$1)+4,0) -> 1500 | AC27: =$K27+VLOOKUP($B27,Tablo1[],MONTH(AC$1)+4,0) -> 1500 | AE27: =$K27+VLOOKUP($B27,Tablo1[],MONTH(AE$1)+4,0) -> 1500 | AG27: =$K27+VLOOKUP($B27,Tablo1[],MONTH(AG$1)+4,0) -> 1500 | AI27: =$K27+VLOOKUP($B27,Tablo1[],MONTH(AI$1)+4,0) -> 1500
A28: 26 | B28: A-BLOK DAİRE 26 | C28: A | D28: 26 | G28: Hüsnü Sümer | K28: 1500 | W28: =$K28+VLOOKUP($B28,Tablo1[],MONTH(W$1)+4,0) -> 1500 | X28: 1500 | Y28: =$K28+VLOOKUP($B28,Tablo1[],MONTH(Y$1)+4,0) -> 1500 | Z28: 1500 | AA28: =$K28+VLOOKUP($B28,Tablo1[],MONTH(AA$1)+4,0) -> 1500 | AC28: =$K28+VLOOKUP($B28,Tablo1[],MONTH(AC$1)+4,0) -> 1500 | AE28: =$K28+VLOOKUP($B28,Tablo1[],MONTH(AE$1)+4,0) -> 1500 | AG28: =$K28+VLOOKUP($B28,Tablo1[],MONTH(AG$1)+4,0) -> 1500 | AI28: =$K28+VLOOKUP($B28,Tablo1[],MONTH(AI$1)+4,0) -> 1500
A29: 27 | B29: A-BLOK DAİRE 27 | C29: A | D29: 27 | G29: Lütfiye Metin | K29: 1500 | W29: =$K29+VLOOKUP($B29,Tablo1[],MONTH(W$1)+4,0) -> 1500 | Y29: =$K29+VLOOKUP($B29,Tablo1[],MONTH(Y$1)+4,0) -> 1500 | AA29: =$K29+VLOOKUP($B29,Tablo1[],MONTH(AA$1)+4,0) -> 1500 | AC29: =$K29+VLOOKUP($B29,Tablo1[],MONTH(AC$1)+4,0) -> 1500 | AE29: =$K29+VLOOKUP($B29,Tablo1[],MONTH(AE$1)+4,0) -> 1500 | AG29: =$K29+VLOOKUP($B29,Tablo1[],MONTH(AG$1)+4,0) -> 1500 | AI29: =$K29+VLOOKUP($B29,Tablo1[],MONTH(AI$1)+4,0) -> 1500
A30: 1 | B30: B-BLOK KAPICI D. | C30: B | D30: 0 | G30: KAPICI DAİRESİ | K30: 1500 | W30: =$K30+VLOOKUP($B30,Tablo1[],MONTH(W$1)+4,0) -> 1500 | Y30: =$K30+VLOOKUP($B30,Tablo1[],MONTH(Y$1)+4,0) -> 1500 | AA30: =$K30+VLOOKUP($B30,Tablo1[],MONTH(AA$1)+4,0) -> 1500 | AC30: =$K30+VLOOKUP($B30,Tablo1[],MONTH(AC$1)+4,0) -> 1500 | AE30: =$K30+VLOOKUP($B30,Tablo1[],MONTH(AE$1)+4,0) -> 1500 | AG30: =$K30+VLOOKUP($B30,Tablo1[],MONTH(AG$1)+4,0) -> 1500 | AI30: =$K30+VLOOKUP($B30,Tablo1[],MONTH(AI$1)+4,0) -> 1500
A31: 2 | B31: B-BLOK DAİRE 01 | C31: B | D31: 1 | G31: Emine Keçeci | K31: 1500 | W31: =$K31+VLOOKUP($B31,Tablo1[],MONTH(W$1)+4,0) -> 1500 | Y31: =$K31+VLOOKUP($B31,Tablo1[],MONTH(Y$1)+4,0) -> 1500 | AA31: =$K31+VLOOKUP($B31,Tablo1[],MONTH(AA$1)+4,0) -> 1500 | AC31: =$K31+VLOOKUP($B31,Tablo1[],MONTH(AC$1)+4,0) -> 1500 | AE31: =$K31+VLOOKUP($B31,Tablo1[],MONTH(AE$1)+4,0) -> 1500 | AG31: =$K31+VLOOKUP($B31,Tablo1[],MONTH(AG$1)+4,0) -> 1500 | AI31: =$K31+VLOOKUP($B31,Tablo1[],MONTH(AI$1)+4,0) -> 1500
A32: 3 | B32: B-BLOK DAİRE 02 | C32: B | D32: 2 | G32: Sinan Ünsal | K32: 1500 | W32: =$K32+VLOOKUP($B32,Tablo1[],MONTH(W$1)+4,0) -> 1500 | Y32: =$K32+VLOOKUP($B32,Tablo1[],MONTH(Y$1)+4,0) -> 1500 | AA32: =$K32+VLOOKUP($B32,Tablo1[],MONTH(AA$1)+4,0) -> 1500 | AC32: =$K32+VLOOKUP($B32,Tablo1[],MONTH(AC$1)+4,0) -> 1500 | AE32: =$K32+VLOOKUP($B32,Tablo1[],MONTH(AE$1)+4,0) -> 1500 | AG32: =$K32+VLOOKUP($B32,Tablo1[],MONTH(AG$1)+4,0) -> 1500 | AI32: =$K32+VLOOKUP($B32,Tablo1[],MONTH(AI$1)+4,0) -> 1500
A33: 4 | B33: B-BLOK DAİRE 03 | C33: B | D33: 3 | G33: Lütfiye Metin | K33: 1500 | W33: =$K33+VLOOKUP($B33,Tablo1[],MONTH(W$1)+4,0) -> 1500 | Y33: =$K33+VLOOKUP($B33,Tablo1[],MONTH(Y$1)+4,0) -> 1500 | AA33: =$K33+VLOOKUP($B33,Tablo1[],MONTH(AA$1)+4,0) -> 1500 | AC33: =$K33+VLOOKUP($B33,Tablo1[],MONTH(AC$1)+4,0) -> 1500 | AE33: =$K33+VLOOKUP($B33,Tablo1[],MONTH(AE$1)+4,0) -> 1500 | AG33: =$K33+VLOOKUP($B33,Tablo1[],MONTH(AG$1)+4,0) -> 1500 | AI33: =$K33+VLOOKUP($B33,Tablo1[],MONTH(AI$1)+4,0) -> 1500
A34: 5 | B34: B-BLOK DAİRE 04 | C34: B | D34: 4 | G34: Mehmet Keçeci | K34: 1500 | W34: =$K34+VLOOKUP($B34,Tablo1[],MONTH(W$1)+4,0) -> 1500 | Y34: =$K34+VLOOKUP($B34,Tablo1[],MONTH(Y$1)+4,0) -> 1500 | AA34: =$K34+VLOOKUP($B34,Tablo1[],MONTH(AA$1)+4,0) -> 1500 | AC34: =$K34+VLOOKUP($B34,Tablo1[],MONTH(AC$1)+4,0) -> 1500 | AE34: =$K34+VLOOKUP($B34,Tablo1[],MONTH(AE$1)+4,0) -> 1500 | AG34: =$K34+VLOOKUP($B34,Tablo1[],MONTH(AG$1)+4,0) -> 1500 | AI34: =$K34+VLOOKUP($B34,Tablo1[],MONTH(AI$1)+4,0) -> 1500
A35: 6 | B35: B-BLOK DAİRE 05 | C35: B | D35: 5 | G35: Emine Keçeci | K35: 1500 | W35: =$K35+VLOOKUP($B35,Tablo1[],MONTH(W$1)+4,0) -> 1500 | Y35: =$K35+VLOOKUP($B35,Tablo1[],MONTH(Y$1)+4,0) -> 1500 | AA35: =$K35+VLOOKUP($B35,Tablo1[],MONTH(AA$1)+4,0) -> 1500 | AC35: =$K35+VLOOKUP($B35,Tablo1[],MONTH(AC$1)+4,0) -> 1500 | AE35: =$K35+VLOOKUP($B35,Tablo1[],MONTH(AE$1)+4,0) -> 1500 | AG35: =$K35+VLOOKUP($B35,Tablo1[],MONTH(AG$1)+4,0) -> 1500 | AI35: =$K35+VLOOKUP($B35,Tablo1[],MONTH(AI$1)+4,0) -> 1500
A36: 7 | B36: B-BLOK DAİRE 06 | C36: B | D36: 6 | G36: Necmi Çavdar | K36: 1500 | W36: =$K36+VLOOKUP($B36,Tablo1[],MONTH(W$1)+4,0) -> 1500 | X36: 1500 | Y36: =$K36+VLOOKUP($B36,Tablo1[],MONTH(Y$1)+4,0) -> 1500 | Z36: 1500 | AA36: =$K36+VLOOKUP($B36,Tablo1[],MONTH(AA$1)+4,0) -> 1500 | AC36: =$K36+VLOOKUP($B36,Tablo1[],MONTH(AC$1)+4,0) -> 1500 | AE36: =$K36+VLOOKUP($B36,Tablo1[],MONTH(AE$1)+4,0) -> 1500 | AG36: =$K36+VLOOKUP($B36,Tablo1[],MONTH(AG$1)+4,0) -> 1500 | AI36: =$K36+VLOOKUP($B36,Tablo1[],MONTH(AI$1)+4,0) -> 1500
A37: 8 | B37: B-BLOK DAİRE 07 | C37: B | D37: 7 | G37: Sinan Ünsal | K37: 1500 | W37: =$K37+VLOOKUP($B37,Tablo1[],MONTH(W$1)+4,0) -> 1500 | Y37: =$K37+VLOOKUP($B37,Tablo1[],MONTH(Y$1)+4,0) -> 1500 | AA37: =$K37+VLOOKUP($B37,Tablo1[],MONTH(AA$1)+4,0) -> 1500 | AC37: =$K37+VLOOKUP($B37,Tablo1[],MONTH(AC$1)+4,0) -> 1500 | AE37: =$K37+VLOOKUP($B37,Tablo1[],MONTH(AE$1)+4,0) -> 1500 | AG37: =$K37+VLOOKUP($B37,Tablo1[],MONTH(AG$1)+4,0) -> 1500 | AI37: =$K37+VLOOKUP($B37,Tablo1[],MONTH(AI$1)+4,0) -> 1500
A38: 9 | B38: B-BLOK DAİRE 08 | C38: B | D38: 8 | G38: Mehmet Keçeci | K38: 1500 | W38: =$K38+VLOOKUP($B38,Tablo1[],MONTH(W$1)+4,0) -> 1500 | Y38: =$K38+VLOOKUP($B38,Tablo1[],MONTH(Y$1)+4,0) -> 1500 | AA38: =$K38+VLOOKUP($B38,Tablo1[],MONTH(AA$1)+4,0) -> 1500 | AC38: =$K38+VLOOKUP($B38,Tablo1[],MONTH(AC$1)+4,0) -> 1500 | AE38: =$K38+VLOOKUP($B38,Tablo1[],MONTH(AE$1)+4,0) -> 1500 | AG38: =$K38+VLOOKUP($B38,Tablo1[],MONTH(AG$1)+4,0) -> 1500 | AI38: =$K38+VLOOKUP($B38,Tablo1[],MONTH(AI$1)+4,0) -> 1500
A39: 10 | B39: B-BLOK DAİRE 09 | C39: B | D39: 9 | G39: Şerife Büyükgaga | K39: 1500 | W39: =$K39+VLOOKUP($B39,Tablo1[],MONTH(W$1)+4,0) -> 1500 | X39: 1500 | Y39: =$K39+VLOOKUP($B39,Tablo1[],MONTH(Y$1)+4,0) -> 1500 | Z39: 1500 | AA39: =$K39+VLOOKUP($B39,Tablo1[],MONTH(AA$1)+4,0) -> 1500 | AC39: =$K39+VLOOKUP($B39,Tablo1[],MONTH(AC$1)+4,0) -> 1500 | AE39: =$K39+VLOOKUP($B39,Tablo1[],MONTH(AE$1)+4,0) -> 1500 | AG39: =$K39+VLOOKUP($B39,Tablo1[],MONTH(AG$1)+4,0) -> 1500 | AI39: =$K39+VLOOKUP($B39,Tablo1[],MONTH(AI$1)+4,0) -> 1500
A40: 11 | B40: B-BLOK DAİRE 10 | C40: B | D40: 10 | G40: Sinan Ünsal | K40: 1500 | W40: =$K40+VLOOKUP($B40,Tablo1[],MONTH(W$1)+4,0) -> 1500 | Y40: =$K40+VLOOKUP($B40,Tablo1[],MONTH(Y$1)+4,0) -> 1500 | AA40: =$K40+VLOOKUP($B40,Tablo1[],MONTH(AA$1)+4,0) -> 1500 | AC40: =$K40+VLOOKUP($B40,Tablo1[],MONTH(AC$1)+4,0) -> 1500 | AE40: =$K40+VLOOKUP($B40,Tablo1[],MONTH(AE$1)+4,0) -> 1500 | AG40: =$K40+VLOOKUP($B40,Tablo1[],MONTH(AG$1)+4,0) -> 1500 | AI40: =$K40+VLOOKUP($B40,Tablo1[],MONTH(AI$1)+4,0) -> 1500
...

Sheet DOĞALGAZ ABONELİK
A1: S.NO. | C1: BLOK | D1: DAİRE NO | E1: NİTELİGİ | F1: MT2 | G1: KAT MALİKİ İSMİ | H1: YAPILMADI | I1: YAPILDI
A2: 1 | B2: A-BLOK KREŞ | C2: A | D2: 1 | G2: Sinan Ünsal | H2: *
A3: 2 | B3: A-BLOK DAİRE 02 | C3: A | D3: 2 | G3: Rıdvan sansar | I3: *
A4: 3 | B4: A-BLOK DAİRE 03 | C4: A | D4: 3 | G4: Sinan Ünsal | H4: *
A5: 4 | B5: A-BLOK DAİRE 04 | C5: A | D5: 4 | G5: BERKCAN DEMİRDÖĞEN | I5: *
A6: 5 | B6: A-BLOK DAİRE 05 | C6: A | D6: 5 | G6: Sinan Ünsal | H6: *
A7: 6 | B7: A-BLOK DAİRE 06 | C7: A | D7: 6 | G7: Sinan Ünsal | H7: *
A8: 7 | B8: A-BLOK DAİRE 07 | C8: A | D8: 7 | G8: Sinan Ural | I8: *
A9: 8 | B9: A-BLOK DAİRE 08 | C9: A | D9: 8 | G9: Özgür Bozkurt | I9: *
A10: 9 | B10: A-BLOK DAİRE 09 | C10: A | D10: 9 | G10: Numan Küçük | I10: *
A11: 10 | B11: A-BLOK DAİRE 10 | C11: A | D11: 10 | G11: Murat Yıldırım | I11: *
A12: 11 | B12: A-BLOK DAİRE 11 | C12: A | D12: 11 | G12: Bülent Kermen | I12: *
A13: 12 | B13: A-BLOK DAİRE 12 | C13: A | D13: 12 | G13: Semiha Tüzün | H13: *
A14: 13 | B14: A-BLOK DAİRE 13 | C14: A | D14: 13 | G14: Ahmet Aykut YILDIZ | I14: *
A15: 14 | B15: A-BLOK DAİRE 14 | C15: A | D15: 14 | G15: Uğur Burak Meriç | I15: *
A16: 15 | B16: A-BLOK DAİRE 15 | C16: A | D16: 15 | G16: Soner Çağlayan | I16: *
A17: 16 | B17: A-BLOK DAİRE 16 | C17: A | D17: 16 | G17: Muhammet Ali Bulut | I17: *
A18: 17 | B18: A-BLOK DAİRE 17 | C18: A | D18: 17 | G18: Gamze Şengün | I18: *
A19: 18 | B19: A-BLOK DAİRE 18 | C19: A | D19: 18 | G19: Sude Karabulut | I19: *
A20: 19 | B20: A-BLOK DAİRE 19 | C20: A | D20: 19 | G20: Nesimi yanar | I20: *
A21: 20 | B21: A-BLOK DAİRE 20 | C21: A | D21: 20 | G21: Murat Doğruyol | I21: *
A22: 21 | B22: A-BLOK DAİRE 21 | C22: A | D22: 21 | G22: Mehmet Saruhan | H22: *
A23: 22 | B23: A-BLOK DAİRE 22 | C23: A | D23: 22 | G23: Filiz Bora | I23: *
A24: 23 | B24: A-BLOK DAİRE 23 | C24: A | D24: 23 | G24: Kemal Aradan | I24: *
A25: 24 | B25: A-BLOK DAİRE 24 | C25: A | D25: 24 | G25: Nevin Köyatası | I25: *
A26: 25 | B26: A-BLOK DAİRE 25 | C26: A | D26: 25 | G26: Ümit Kula | I26: *
A27: 26 | B27: A-BLOK DAİRE 26 | C27: A | D27: 26 | G27: Hüsnü Sümer | I27: *
A28: 27 | B28: A-BLOK DAİRE 27 | C28: A | D28: 27 | G28: Lütfiye Metin | H28: *
A29: 1 | B29: B-BLOK KAPICI D. | C29: B | D29: 0 | G29: KAPICI DAİRESİ | H29: *
A30: 2 | B30: B-BLOK DAİRE 01 | C30: B | D30: 1 | G30: Emine Keçeci | I30: *
A31: 3 | B31: B-BLOK DAİRE 02 | C31: B | D31: 2 | G31: Sinan Ünsal | H31: *
A32: 4 | B32: B-BLOK DAİRE 03 | C32: B | D32: 3 | G32: Lütfiye Metin | H32: *
A33: 5 | B33: B-BLOK DAİRE 04 | C33: B | D33: 4 | G33: Mehmet Keçeci | I33: *
A34: 6 | B34: B-BLOK DAİRE 05 | C34: B | D34: 5 | G34: Emine Keçeci | I34: *
A35: 7 | B35: B-BLOK DAİRE 06 | C35: B | D35: 6 | G35: Necmi Çavdar | I35: *
A36: 8 | B36: B-BLOK DAİRE 07 | C36: B | D36: 7 | G36: Sinan Ünsal | H36: *
A37: 9 | B37: B-BLOK DAİRE 08 | C37: B | D37: 8 | G37: Mehmet Keçeci | I37: *
A38: 10 | B38: B-BLOK DAİRE 09 | C38: B | D38: 9 | G38: Şerife Büyükgaga | I38: *
A39: 11 | B39: B-BLOK DAİRE 10 | C39: B | D39: 10 | G39: Sinan Ünsal | H39: *
A40: 12 | B40: B-BLOK DAİRE 11 | C40: B | D40: 11 | G40: Sinan Ünsal | H40: *
...

Sheet DOGALGAZ_FATURA
A1: TROASPARK SİTESİ DAİRE ISITMA FATURA DÖKÜMÜ | T1: Dönem | U1: 1.05.2024
A2: =CONCATENATE(UPPER(TEXT(($U$1)-1,"AAAA"))," - ",UPPER(TEXT(($U$1),"AAAA"))," AYLARI KULLANIM VE ÖDEME İCMALİ") -> NİSAN - MAYIS AYLARI KULLANIM VE ÖDEME İCMALİ
A3: TOPLAM FATURA TUTARI | D3: =HLOOKUP($U$1,DOGALGAZ_DATA!$E$1:$P$4,3,0) -> 0 | G3: BR MT2 TUTARI | I3: =HLOOKUP($U$1,DOGALGAZ_DATA!$E$1:$P$4,4,0) -> 0 | K3: GECİKME CEZASI FAİZ ORANI | O3: 0.4
A4: BLOK | B4: DAİRE | C4: MT² | D4: ÖDENECEK TUTAR | E4: BLOK | F4: DAİRE | G4: MT² | H4: ÖDENECEK TUTAR | I4: BLOK | J4: DAİRE | K4: MT² | L4: ÖDENECEK TUTAR | M4: BLOK | N4: DAİRE | O4: MT² | P4: ÖDENECEK TUTAR
A5: A-BLOK | B5: KREŞ | C5: 404 | D5: =VLOOKUP(CONCATENATE(A5," ",B5),Tablo1[],MONTH($U$1)+4,0) -> 0 | E5: B-BLOK | F5: DAİRE 01 | G5: 94 | H5: =VLOOKUP(CONCATENATE(E5," ",F5),Tablo1[],MONTH($U$1)+4,0) -> 0 | I5: C-BLOK | J5: DÜKKAN 01 | K5: 90 | L5: =VLOOKUP(CONCATENATE(I5," ",J5),Tablo1[],MONTH($U$1)+4,0) -> 0 | M5: C-BLOK | N5: DAİRE 33 | O5: 49 | P5: =VLOOKUP(CONCATENATE(M5," ",N5),Tablo1[],MONTH($U$1)+4,0) -> 0
A6: A-BLOK | B6: DAİRE 02 | C6: 65 | D6: =VLOOKUP(CONCATENATE(A6," ",B6),Tablo1[],MONTH($U$1)+4,0) -> 0 | E6: B-BLOK | F6: DAİRE 02 | G6: 120 | H6: =VLOOKUP(CONCATENATE(E6," ",F6),Tablo1[],MONTH($U$1)+4,0) -> 0 | I6: C-BLOK | J6: DÜKKAN 02 | K6: 45 | L6: =VLOOKUP(CONCATENATE(I6," ",J6),Tablo1[],MONTH($U$1)+4,0) -> 0 | M6: C-BLOK | N6: DAİRE 34 | O6: 101 | P6: =VLOOKUP(CONCATENATE(M6," ",N6),Tablo1[],MONTH($U$1)+4,0) -> 0
A7: A-BLOK | B7: DAİRE 03 | C7: 85 | D7: =VLOOKUP(CONCATENATE(A7," ",B7),Tablo1[],MONTH($U$1)+4,0) -> 0 | E7: B-BLOK | F7: DAİRE 03 | G7: 120 | H7: =VLOOKUP(CONCATENATE(E7," ",F7),Tablo1[],MONTH($U$1)+4,0) -> 0 | I7: C-BLOK | J7: DÜKKAN 03 | K7: 45 | L7: =VLOOKUP(CONCATENATE(I7," ",J7),Tablo1[],MONTH($U$1)+4,0) -> 0 | M7: C-BLOK | N7: DAİRE 35 | O7: 100 | P7: =VLOOKUP(CONCATENATE(M7," ",N7),Tablo1[],MONTH($U$1)+4,0) -> 0
A8: A-BLOK | B8: DAİRE 04 | C8: 128 | D8: =VLOOKUP(CONCATENATE(A8," ",B8),Tablo1[],MONTH($U$1)+4,0) -> 0 | E8: B-BLOK | F8: DAİRE 04 | G8: 110 | H8: =VLOOKUP(CONCATENATE(E8," ",F8),Tablo1[],MONTH($U$1)+4,0) -> 0 | I8: C-BLOK | J8: DÜKKAN 04 | K8: 90 | L8: =VLOOKUP(CONCATENATE(I8," ",J8),Tablo1[],MONTH($U$1)+4,0) -> 0 | M8: C-BLOK | N8: DAİRE 36 | O8: 51 | P8: =VLOOKUP(CONCATENATE(M8," ",N8),Tablo1[],MONTH($U$1)+4,0) -> 0
A9: A-BLOK | B9: DAİRE 05 | C9: 128 | D9: =VLOOKUP(CONCATENATE(A9," ",B9),Tablo1[],MONTH($U$1)+4,0) -> 0 | E9: B-BLOK | F9: DAİRE 05 | G9: 126 | H9: =VLOOKUP(CONCATENATE(E9," ",F9),Tablo1[],MONTH($U$1)+4,0) -> 0 | I9: C-BLOK | J9: DAİRE 05 | K9: 80 | L9: =VLOOKUP(CONCATENATE(I9," ",J9),Tablo1[],MONTH($U$1)+4,0) -> 0 | M9: C-BLOK | N9: DAİRE 37 | O9: 97 | P9: =VLOOKUP(CONCATENATE(M9," ",N9),Tablo1[],MONTH($U$1)+4,0) -> 0
A10: A-BLOK | B10: DAİRE 06 | C10: 126 | D10: =VLOOKUP(CONCATENATE(A10," ",B10),Tablo1[],MONTH($U$1)+4,0) -> 0 | E10: B-BLOK | F10: DAİRE 06 | G10: 126 | H10: =VLOOKUP(CONCATENATE(E10," ",F10),Tablo1[],MONTH($U$1)+4,0) -> 0 | I10: C-BLOK | J10: DAİRE 06 | K10: 49 | L10: =VLOOKUP(CONCATENATE(I10," ",J10),Tablo1[],MONTH($U$1)+4,0) -> 0 | M10: C-BLOK | N10: DAİRE 38 | O10: 100 | P10: =VLOOKUP(CONCATENATE(M10," ",N10),Tablo1[],MONTH($U$1)+4,0) -> 0
A11: A-BLOK | B11: DAİRE 07 | C11: 126 | D11: =VLOOKUP(CONCATENATE(A11," ",B11),Tablo1[],MONTH($U$1)+4,0) -> 0 | E11: B-BLOK | F11: DAİRE 07 | G11: 128 | H11: =VLOOKUP(CONCATENATE(E11," ",F11),Tablo1[],MONTH($U$1)+4,0) -> 0 | I11: C-BLOK | J11: DAİRE 07 | K11: 97 | L11: =VLOOKUP(CONCATENATE(I11," ",J11),Tablo1[],MONTH($U$1)+4,0) -> 0 | M11: C-BLOK | N11: DAİRE 39 | O11: 49 | P11: =VLOOKUP(CONCATENATE(M11," ",N11),Tablo1[],MONTH($U$1)+4,0) -> 0
A12: A-BLOK | B12: DAİRE 08 | C12: 128 | D12: =VLOOKUP(CONCATENATE(A12," ",B12),Tablo1[],MONTH($U$1)+4,0) -> 0 | E12: B-BLOK | F12: DAİRE 08 | G12: 128 | H12: =VLOOKUP(CONCATENATE(E12," ",F12),Tablo1[],MONTH($U$1)+4,0) -> 0 | I12: C-BLOK | J12: DAİRE 08 | K12: 51 | L12: =VLOOKUP(CONCATENATE(I12," ",J12),Tablo1[],MONTH($U$1)+4,0) -> 0 | M12: C-BLOK | N12: DAİRE 40 | O12: 49 | P12: =VLOOKUP(CONCATENATE(M12," ",N12),Tablo1[],MONTH($U$1)+4,0) -> 0
A13: A-BLOK | B13: DAİRE 09 | C13: 128 | D13: =VLOOKUP(CONCATENATE(A13," ",B13),Tablo1[],MONTH($U$1)+4,0) -> 0 | E13: B-BLOK | F13: DAİRE 09 | G13: 126 | H13: =VLOOKUP(CONCATENATE(E13," ",F13),Tablo1[],MONTH($U$1)+4,0) -> 0 | I13: C-BLOK | J13: DAİRE 09 | K13: 97 | L13: =VLOOKUP(CONCATENATE(I13," ",J13),Tablo1[],MONTH($U$1)+4,0) -> 0 | M13: C-BLOK | N13: DAİRE 41 | O13: 101 | P13: =VLOOKUP(CONCATENATE(M13," ",N13),Tablo1[],MONTH($U$1)+4,0) -> 0
A14: A-BLOK | B14: DAİRE 10 | C14: 126 | D14: =VLOOKUP(CONCATENATE(A14," ",B14),Tablo1[],MONTH($U$1)+4,0) -> 0 | E14: B-BLOK | F14: DAİRE 10 | G14: 126 | H14: =VLOOKUP(CONCATENATE(E14," ",F14),Tablo1[],MONTH($U$1)+4,0) -> 0 | I14: C-BLOK | J14: DAİRE 10 | K14: 100 | L14: =VLOOKUP(CONCATENATE(I14," ",J14),Tablo1[],MONTH($U$1)+4,0) -> 0 | M14: C-BLOK | N14: DAİRE 42 | O14: 100 | P14: =VLOOKUP(CONCATENATE(M14," ",N14),Tablo1[],MONTH($U$1)+4,0) -> 0
A15: A-BLOK | B15: DAİRE 11 | C15: 126 | D15: =VLOOKUP(CONCATENATE(A15," ",B15),Tablo1[],MONTH($U$1)+4,0) -> 0 | E15: B-BLOK | F15: DAİRE 11 | G15: 128 | H15: =VLOOKUP(CONCATENATE(E15," ",F15),Tablo1[],MONTH($U$1)+4,0) -> 0 | I15: C-BLOK | J15: DAİRE 11 | K15: 49 | L15: =VLOOKUP(CONCATENATE(I15," ",J15),Tablo1[],MONTH($U$1)+4,0) -> 0 | M15: C-BLOK | N15: DAİRE 43 | O15: 51 | P15: =VLOOKUP(CONCATENATE(M15," ",N15),Tablo1[],MONTH($U$1)+4,0) -> 0
A16: A-BLOK | B16: DAİRE 12 | C16: 128 | D16: =VLOOKUP(CONCATENATE(A16," ",B16),Tablo1[],MONTH($U$1)+4,0) -> 0 | E16: B-BLOK | F16: DAİRE 12 | G16: 128 | H16: =VLOOKUP(CONCATENATE(E16," ",F16),Tablo1[],MONTH($U$1)+4,0) -> 0 | I16: C-BLOK | J16: DAİRE 12 | K16: 49 | L16: =VLOOKUP(CONCATENATE(I16," ",J16),Tablo1[],MONTH($U$1)+4,0) -> 0 | M16: C-BLOK | N16: DAİRE 44 | O16: 97 | P16: =VLOOKUP(CONCATENATE(M16," ",N16),Tablo1[],MONTH($U$1)+4,0) -> 0
... A28: A-BLOK | B28: DAİRE 24 | C28: 128 | D28: =VLOOKUP(CONCATENATE(A28," ",B28),Tablo1[],MONTH($U$1)+4,0) -> 0 | E28: B-BLOK | F28: DAİRE 24 | G28: 128 | H28: =VLOOKUP(CONCATENATE(E28," ",F28),Tablo1[],MONTH($U$1)+4,0) -> 0 | I28: C-BLOK | J28: DAİRE 24 | K28: 100 | L28: =VLOOKUP(CONCATENATE(I28," ",J28),Tablo1[],MONTH($U$1)+4,0) -> 0 | M28: C-BLOK | N28: DAİRE 56 | O28: 100 | P28: =VLOOKUP(CONCATENATE(M28," ",N28),Tablo1[],MONTH($U$1)+4,0) -> 0
A29: A-BLOK | B29: DAİRE 25 | C29: 128 | D29: =VLOOKUP(CONCATENATE(A29," ",B29),Tablo1[],MONTH($U$1)+4,0) -> 0 | E29: B-BLOK | F29: DAİRE 25 | G29: 126 | H29: =VLOOKUP(CONCATENATE(E29," ",F29),Tablo1[],MONTH($U$1)+4,0) -> 0 | I29: C-BLOK | J29: DAİRE 25 | K29: 49 | L29: =VLOOKUP(CONCATENATE(I29," ",J29),Tablo1[],MONTH($U$1)+4,0) -> 0
A30: A-BLOK | B30: DAİRE 26 | C30: 126 | D30: =VLOOKUP(CONCATENATE(A30," ",B30),Tablo1[],MONTH($U$1)+4,0) -> 0 | E30: B-BLOK | F30: DAİRE 26 | G30: 126 | H30: =VLOOKUP(CONCATENATE(E30," ",F30),Tablo1[],MONTH($U$1)+4,0) -> 0 | I30: C-BLOK | J30: DAİRE 26 | K30: 49 | L30: =VLOOKUP(CONCATENATE(I30," ",J30),Tablo1[],MONTH($U$1)+4,0) -> 0
A31: A-BLOK | B31: DAİRE 27 | C31: 126 | D31: =VLOOKUP(CONCATENATE(A31," ",B31),Tablo1[],MONTH($U$1)+4,0) -> 0 | E31: B-BLOK | F31: DAİRE 27 | G31: 128 | H31: =VLOOKUP(CONCATENATE(E31," ",F31),Tablo1[],MONTH($U$1)+4,0) -> 0 | I31: C-BLOK | J31: DAİRE 27 | K31: 101 | L31: =VLOOKUP(CONCATENATE(I31," ",J31),Tablo1[],MONTH($U$1)+4,0) -> 0 | M31: BLOKLAR TOPLAMI MT² | P31: =SUM($C$5:$C$35,$G$5:$G$37,$K$5:$K$36,$O$5:$O$28) -> 12500
A32: A-BLOK | B32: DAİRE 28 | C32: 128 | D32: =VLOOKUP(CONCATENATE(A32," ",B32),Tablo1[],MONTH($U$1)+4,0) -> 0 | E32: B-BLOK | F32: DAİRE 28 | G32: 128 | H32: =VLOOKUP(CONCATENATE(E32," ",F32),Tablo1[],MONTH($U$1)+4,0) -> 0 | I32: C-BLOK | J32: DAİRE 28 | K32: 100 | L32: =VLOOKUP(CONCATENATE(I32," ",J32),Tablo1[],MONTH($U$1)+4,0) -> 0
A33: A-BLOK | B33: DAİRE 29 | C33: 128 | D33: =VLOOKUP(CONCATENATE(A33," ",B33),Tablo1[],MONTH($U$1)+4,0) -> 0 | E33: B-BLOK | F33: DAİRE 29 | G33: 126 | H33: =VLOOKUP(CONCATENATE(E33," ",F33),Tablo1[],MONTH($U$1)+4,0) -> 0 | I33: C-BLOK | J33: DAİRE 29 | K33: 51 | L33: =VLOOKUP(CONCATENATE(I33," ",J33),Tablo1[],MONTH($U$1)+4,0) -> 0
A34: A-BLOK | B34: DAİRE 30 | C34: 126 | D34: =VLOOKUP(CONCATENATE(A34," ",B34),Tablo1[],MONTH($U$1)+4,0) -> 0 | E34: B-BLOK | F34: DAİRE 30 | G34: 126 | H34: =VLOOKUP(CONCATENATE(E34," ",F34),Tablo1[],MONTH($U$1)+4,0) -> 0 | I34: C-BLOK | J34: DAİRE 30 | K34: 97 | L34: =VLOOKUP(CONCATENATE(I34," ",J34),Tablo1[],MONTH($U$1)+4,0) -> 0 | M34: SON ÖDEME TARİHİ
A35: A-BLOK | B35: DAİRE 31 | C35: 126 | D35: =VLOOKUP(CONCATENATE(A35," ",B35),Tablo1[],MONTH($U$1)+4,0) -> 0 | E35: B-BLOK | F35: DAİRE 31 | G35: 128 | H35: =VLOOKUP(CONCATENATE(E35," ",F35),Tablo1[],MONTH($U$1)+4,0) -> 0 | I35: C-BLOK | J35: DAİRE 31 | K35: 100 | L35: =VLOOKUP(CONCATENATE(I35," ",J35),Tablo1[],MONTH($U$1)+4,0) -> 0 | M35: =HLOOKUP($U$1,DOGALGAZ_DATA!$E$1:$P$4,2,0)-1 -> 45431 | N35: =HLOOKUP($U$1,DOGALGAZ_DATA!$E$1:$P$4,4,0) -> 0 | O35: =HLOOKUP($U$1,DOGALGAZ_DATA!$E$1:$P$4,4,0) -> 0 | P35: =HLOOKUP($U$1,DOGALGAZ_DATA!$E$1:$P$4,4,0) -> 0
A36: A BLOK TOPLAM MT2 | E36: B-BLOK | F36: DAİRE 32 | G36: 128 | H36: =VLOOKUP(CONCATENATE(E36," ",F36),Tablo1[],MONTH($U$1)+4,0) -> 0 | I36: C-BLOK | J36: DAİRE 32 | K36: 49 | L36: =VLOOKUP(CONCATENATE(I36," ",J36),Tablo1[],MONTH($U$1)+4,0) -> 0 | M36: SAĞLIKLI GÜNLER.
E37: B-BLOK | F37: KAPICI D. | G37: 65 | H37: =VLOOKUP(CONCATENATE(E37," ",F37),Tablo1[],MONTH($U$1)+4,0) -> 0 | I37: C BLOK TOPLAM MT2
E38: B BLOK TOPLAM MT2

Sheet DOGALGAZ_DATA
B1: Dönem | E1: =Tablo1[[#Headers],[1.01.2024]] -> 1.01.2024 | F1: =Tablo1[[#Headers],[1.02.2024]] -> 1.02.2024 | G1: =Tablo1[[#Headers],[1.03.2024]] -> 1.03.2024 | H1: =Tablo1[[#Headers],[1.04.2024]] -> 1.04.2024 | I1: =Tablo1[[#Headers],[1.05.2024]] -> 1.05.2024 | J1: =Tablo1[[#Headers],[1.06.2024]] -> 1.06.2024 | K1: =Tablo1[[#Headers],[1.07.2024]] -> 1.07.2024 | L1: =Tablo1[[#Headers],[1.08.2024]] -> 1.08.2024 | M1: =Tablo1[[#Headers],[1.09.2024]] -> 1.09.2024 | N1: =Tablo1[[#Headers],[1.10.2024]] -> 1.10.2024 | O1: =Tablo1[[#Headers],[1.11.2024]] -> 1.11.2024 | P1: =Tablo1[[#Headers],[1.12.2024]] -> 1.12.2024
B2: Son Ödeme Tarihi | E2: 45309 | F2: 45340 | G2: 45369 | H2: 45397 | I2: 45432
B3: Fatura Tutarı
B4: Birim Fiyat | E4: =E3/12500 -> 0 | F4: =F3/12500 -> 0 | G4: =G3/12500 -> 0 | H4: =H3/12500 -> 0 | I4: =I3/12500 -> 0 | J4: =J3/12500 -> 0 | K4: =K3/12500 -> 0 | L4: =L3/12500 -> 0 | ... P4: =P3/12500 -> 0
A5: Sütun1 | B5: BLOK | C5: DAİRE | D5: MT² | E5: 1.01.2024 | F5: 1.02.2024 | G5: 1.03.2024 | H5: 1.04.2024 | I5: 1.05.2024 | J5: 1.06.2024 | K5: 1.07.2024 | L5: 1.08.2024 | M5: 1.09.2024 | N5: 1.10.2024 | O5: 1.11.2024 | P5: 1.12.2024
A6: =CONCATENATE(Tablo1[[#This Row],[BLOK]]," ",Tablo1[[#This Row],[DAİRE]]) -> A-BLOK KREŞ | B6: A-BLOK | C6: KREŞ | D6: 404 | E6: =ROUNDUP(E$4*$D6,1) -> 0 | F6: =ROUNDUP(F$4*$D6,1) -> 0 | G6: =ROUNDUP(G$4*$D6,1) -> 0 | H6: =ROUNDUP(H$4*$D6,1) -> 0 | I6: =ROUNDUP(I$4*$D6,1) -> 0 | J6: =ROUNDUP(J$4*$D6,1) -> 0 | K6: =ROUNDUP(K$4*$D6,1) -> 0 | L6: =ROUNDUP(L$4*$D6,1) -> 0 | ... P6: =ROUNDUP(P$4*$D6,1) -> 0
A7: =CONCATENATE(Tablo1[[#This Row],[BLOK]]," ",Tablo1[[#This Row],[DAİRE]]) -> A-BLOK DAİRE 02 | B7: A-BLOK | C7: DAİRE 02 | D7: 65 | E7: =ROUNDUP(E$4*$D7,1) -> 0 | F7: =ROUNDUP(F$4*$D7,1) -> 0 | G7: =ROUNDUP(G$4*$D7,1) -> 0 | H7: =ROUNDUP(H$4*$D7,1) -> 0 | I7: =ROUNDUP(I$4*$D7,1) -> 0 | J7: =ROUNDUP(J$4*$D7,1) -> 0 | K7: =ROUNDUP(K$4*$D7,1) -> 0 | L7: =ROUNDUP(L$4*$D7,1) -> 0 | ... P7: =ROUNDUP(P$4*$D7,1) -> 0
A8: =CONCATENATE(Tablo1[[#This Row],[BLOK]]," ",Tablo1[[#This Row],[DAİRE]]) -> A-BLOK DAİRE 03 | B8: A-BLOK | C8: DAİRE 03 | D8: 85 | E8: =ROUNDUP(E$4*$D8,1) -> 0 | F8: =ROUNDUP(F$4*$D8,1) -> 0 | G8: =ROUNDUP(G$4*$D8,1) -> 0 | H8: =ROUNDUP(H$4*$D8,1) -> 0 | I8: =ROUNDUP(I$4*$D8,1) -> 0 | J8: =ROUNDUP(J$4*$D8,1) -> 0 | K8: =ROUNDUP(K$4*$D8,1) -> 0 | L8: =ROUNDUP(L$4*$D8,1) -> 0 | ... P8: =ROUNDUP(P$4*$D8,1) -> 0
A9: =CONCATENATE(Tablo1[[#This Row],[BLOK]]," ",Tablo1[[#This Row],[DAİRE]]) -> A-BLOK DAİRE 04 | B9: A-BLOK | C9: DAİRE 04 | D9: 128 | E9: =ROUNDUP(E$4*$D9,1) -> 0 | F9: =ROUNDUP(F$4*$D9,1) -> 0 | G9: =ROUNDUP(G$4*$D9,1) -> 0 | H9: =ROUNDUP(H$4*$D9,1) -> 0 | I9: =ROUNDUP(I$4*$D9,1) -> 0 | J9: =ROUNDUP(J$4*$D9,1) -> 0 | K9: =ROUNDUP(K$4*$D9,1) -> 0 | L9: =ROUNDUP(L$4*$D9,1) -> 0 | ... P9: =ROUNDUP(P$4*$D9,1) -> 0
A10: =CONCATENATE(Tablo1[[#This Row],[BLOK]]," ",Tablo1[[#This Row],[DAİRE]]) -> A-BLOK DAİRE 05 | B10: A-BLOK | C10: DAİRE 05 | D10: 128 | E10: =ROUNDUP(E$4*$D10,1) -> 0 | F10: =ROUNDUP(F$4*$D10,1) -> 0 | G10: =ROUNDUP(G$4*$D10,1) -> 0 | H10: =ROUNDUP(H$4*$D10,1) -> 0 | I10: =ROUNDUP(I$4*$D10,1) -> 0 | J10: =ROUNDUP(J$4*$D10,1) -> 0 | K10: =ROUNDUP(K$4*$D10,1) -> 0 | L10: =ROUNDUP(L$4*$D10,1) -> 0 | ... P10: =ROUNDUP(P$4*$D10,1) -> 0
A11: =CONCATENATE(Tablo1[[#This Row],[BLOK]]," ",Tablo1[[#This Row],[DAİRE]]) -> A-BLOK DAİRE 06 | B11: A-BLOK | C11: DAİRE 06 | D11: 126 | E11: =ROUNDUP(E$4*$D11,1) -> 0 | F11: =ROUNDUP(F$4*$D11,1) -> 0 | G11: =ROUNDUP(G$4*$D11,1) -> 0 | H11: =ROUNDUP(H$4*$D11,1) -> 0 | I11: =ROUNDUP(I$4*$D11,1) -> 0 | J11: =ROUNDUP(J$4*$D11,1) -> 0 | K11: =ROUNDUP(K$4*$D11,1) -> 0 | L11: =ROUNDUP(L$4*$D11,1) -> 0 | ... P11: =ROUNDUP(P$4*$D11,1) -> 0
A12: =CONCATENATE(Tablo1[[#This Row],[BLOK]]," ",Tablo1[[#This Row],[DAİRE]]) -> A-BLOK DAİRE 07 | B12: A-BLOK | C12: DAİRE 07 | D12: 126 | E12: =ROUNDUP(E$4*$D12,1) -> 0 | F12: =ROUNDUP(F$4*$D12,1) -> 0 | G12: =ROUNDUP(G$4*$D12,1) -> 0 | H12: =ROUNDUP(H$4*$D12,1) -> 0 | I12: =ROUNDUP(I$4*$D12,1) -> 0 | J12: =ROUNDUP(J$4*$D12,1) -> 0 | K12: =ROUNDUP(K$4*$D12,1) -> 0 | L12: =ROUNDUP(L$4*$D12,1) -> 0 | ... P12: =ROUNDUP(P$4*$D12,1) -> 0
A13: =CONCATENATE(Tablo1[[#This Row],[BLOK]]," ",Tablo1[[#This Row],[DAİRE]]) -> A-BLOK DAİRE 08 | B13: A-BLOK | C13: DAİRE 08 | D13: 128 | E13: =ROUNDUP(E$4*$D13,1) -> 0 | F13: =ROUNDUP(F$4*$D13,1) -> 0 | G13: =ROUNDUP(G$4*$D13,1) -> 0 | H13: =ROUNDUP(H$4*$D13,1) -> 0 | I13: =ROUNDUP(I$4*$D13,1) -> 0 | J13: =ROUNDUP(J$4*$D13,1) -> 0 | K13: =ROUNDUP(K$4*$D13,1) -> 0 | L13: =ROUNDUP(L$4*$D13,1) -> 0 | ... P13: =ROUNDUP(P$4*$D13,1) -> 0
A14: =CONCATENATE(Tablo1[[#This Row],[BLOK]]," ",Tablo1[[#This Row],[DAİRE]]) -> A-BLOK DAİRE 09 | B14: A-BLOK | C14: DAİRE 09 | D14: 128 | E14: =ROUNDUP(E$4*$D14,1) -> 0 | F14: =ROUNDUP(F$4*$D14,1) -> 0 | G14: =ROUNDUP(G$4*$D14,1) -> 0 | H14: =ROUNDUP(H$4*$D14,1) -> 0 | I14: =ROUNDUP(I$4*$D14,1) -> 0 | J14: =ROUNDUP(J$4*$D14,1) -> 0 | K14: =ROUNDUP(K$4*$D14,1) -> 0 | L14: =ROUNDUP(L$4*$D14,1) -> 0 | ... P14: =ROUNDUP(P$4*$D14,1) -> 0
A15: =CONCATENATE(Tablo1[[#This Row],[BLOK]]," ",Tablo1[[#This Row],[DAİRE]]) -> A-BLOK DAİRE 10 | B15: A-BLOK | C15: DAİRE 10 | D15: 126 | E15: =ROUNDUP(E$4*$D15,1) -> 0 | F15: =ROUNDUP(F$4*$D15,1) -> 0 | G15: =ROUNDUP(G$4*$D15,1) -> 0 | H15: =ROUNDUP(H$4*$D15,1) -> 0 | I15: =ROUNDUP(I$4*$D15,1) -> 0 | J15: =ROUNDUP(J$4*$D15,1) -> 0 | K15: =ROUNDUP(K$4*$D15,1) -> 0 | L15: =ROUNDUP(L$4*$D15,1) -> 0 | ... P15: =ROUNDUP(P$4*$D15,1) -> 0
A16: =CONCATENATE(Tablo1[[#This Row],[BLOK]]," ",Tablo1[[#This Row],[DAİRE]]) -> A-BLOK DAİRE 11 | B16: A-BLOK | C16: DAİRE 11 | D16: 126 | E16: =ROUNDUP(E$4*$D16,1) -> 0 | F16: =ROUNDUP(F$4*$D16,1) -> 0 | G16: =ROUNDUP(G$4*$D16,1) -> 0 | H16: =ROUNDUP(H$4*$D16,1) -> 0 | I16: =ROUNDUP(I$4*$D16,1) -> 0 | J16: =ROUNDUP(J$4*$D16,1) -> 0 | K16: =ROUNDUP(K$4*$D16,1) -> 0 | L16: =ROUNDUP(L$4*$D16,1) -> 0 | ... P16: =ROUNDUP(P$4*$D16,1) -> 0
A17: =CONCATENATE(Tablo1[[#This Row],[BLOK]]," ",Tablo1[[#This Row],[DAİRE]]) -> A-BLOK DAİRE 12 | B17: A-BLOK | C17: DAİRE 12 | D17: 128 | E17: =ROUNDUP(E$4*$D17,1) -> 0 | F17: =ROUNDUP(F$4*$D17,1) -> 0 | G17: =ROUNDUP(G$4*$D17,1) -> 0 | H17: =ROUNDUP(H$4*$D17,1) -> 0 | I17: =ROUNDUP(I$4*$D17,1) -> 0 | J17: =ROUNDUP(J$4*$D17,1) -> 0 | K17: =ROUNDUP(K$4*$D17,1) -> 0 | L17: =ROUNDUP(L$4*$D17,1) -> 0 | ... P17: =ROUNDUP(P$4*$D17,1) -> 0
... A125: =CONCATENATE(Tablo1[[#This Row],[BLOK]]," ",Tablo1[[#This Row],[DAİRE]]) -> C-BLOK DAİRE 56 | B125: C-BLOK | C125: DAİRE 56 | D125: 100 | E125: =ROUNDUP(E$4*$D125,1) -> 0 | F125: =ROUNDUP(F$4*$D125,1) -> 0 | G125: =ROUNDUP(G$4*$D125,1) -> 0 | H125: =ROUNDUP(H$4*$D125,1) -> 0 | I125: =ROUNDUP(I$4*$D125,1) -> 0 | J125: =ROUNDUP(J$4*$D125,1) -> 0 | K125: =ROUNDUP(K$4*$D125,1) -> 0 | L125: =ROUNDUP(L$4*$D125,1) -> 0 | ... P125: =ROUNDUP(P$4*$D125,1) -> 0
B126: Toplam | E126: =SUBTOTAL(109,Tablo1[1.01.2024]) -> 0 | F126: =SUBTOTAL(109,Tablo1[1.02.2024]) -> 0 | G126: =SUBTOTAL(109,Tablo1[1.03.2024]) -> 0 | H126: =SUBTOTAL(109,Tablo1[1.04.2024]) -> 0 | I126: =SUBTOTAL(109,Tablo1[1.05.2024]) -> 0 | J126: =SUBTOTAL(109,Tablo1[1.06.2024]) -> 0 | K126: =SUBTOTAL(109,Tablo1[1.07.2024]) -> 0 | L126: =SUBTOTAL(109,Tablo1[1.08.2024]) -> 0 | M126: =SUBTOTAL(109,Tablo1[1.09.2024]) -> 0 | N126: =SUBTOTAL(109,Tablo1[1.10.2024]) -> 0 | O126: =SUBTOTAL(109,Tablo1[1.11.2024]) -> 0 | P126: =SUBTOTAL(109,Tablo1[1.12.2024]) -> 0

Sheet DOĞALGAZ AVANS
A1: S.NO. | B1: BLOK | C1: DAİRE NO | E1: NİTELİGİ | F1: MT2 | G1: KAT MALİKİ İSMİ | H1: TC. KİMLİK NO | I1: TELEFON NO | J1: KİRACI İSMİ | K1: TC. KİMLİK NO | L1: TELEFON NO | M1: AVANS YATIRMA DURUMU
A2: 1 | B2: A | C2: 1 | E2: İŞ YERİ | F2: 404
A3: 2 | B3: A | C3: 2 | E3: 1+1 | F3: 65
A4: 3 | B4: A | C4: 3 | E4: 2+1 | F4: 85
A5: 4 | B5: A | C5: 4 | E5: 3+1 | F5: 128
A6: 5 | B6: A | C6: 5 | E6: 3+1 | F6: 128
A7: 6 | B7: A | C7: 6 | E7: 3+1 | F7: 126
A8: 7 | B8: A | C8: 7 | E8: 3+1 | F8: 126
A9: 8 | B9: A | C9: 8 | E9: 3+1 | F9: 128
A10: 9 | B10: A | C10: 9 | E10: 3+1 | F10: 128
A11: 10 | B11: A | C11: 10 | E11: 3+1 | F11: 126
A12: 11 | B12: A | C12: 11 | E12: 3+1 | F12: 126
A13: 12 | B13: A | C13: 12 | E13: 3+1 | F13: 128
... A117: 52 | B117: C | C117: 52 | E117: 2+1 | F117: 100
A118: 53 | B118: C | C118: 53 | D118: aidata yatırmış | E118: 1+1 | F118: 49
A119: 54 | B119: C | C119: 54 | E119: 1+1 | F119: 49
A120: 55 | B120: C | C120: 55 | E120: 2+1 | F120: 101
A121: 56 | B121: C | C121: 56 | E121: 2+1 | F121: 100
